<?xml version="1.0"?>

<robot name="arm"  >


    <link name="base_link">
      <visual>
        <geometry>
            <box size="1 1 1"/>
        </geometry> 
      </visual>
    </link> 

   <link name="link_01">
      <visual>
        <geometry>
          <cylinder length="0.4" radius="0.4"/>
        </geometry>
        <origin xyz="0.0 0.0 0.1" rpy="0.0 0.0 0.0"/>
      </visual>
   </link>

    <joint name="base_link_to_link_01" type="revolute">
        <axis xyz="0 0 1"/>
        <limit lower="-3.14" upper="3.14" effort="1000.0" velocity="0.5"/>
        <origin xyz="0.0 0.0 3" rpy="0.0 0.0 0.0"/>
        <parent link="base_link"/>
        <child link="link_01"/>
    </joint>

    <joint name="link_01_to_link_02" type="revolute">
        <axis xyz="0 1 0"/>
        <limit lower="-3.14" upper="3.14" effort="1000.0" velocity="0.5"/>
        <origin xyz="0.0 0.0 0.4" rpy="0.0 0.0 0.0"/>
        <parent link="link_01"/>
        <child link="link_02"/>
    </joint>

    <link name="link_02">
        <visual>
            <geometry>
                <cylinder length="0.8" radius="0.15"/>
            </geometry>
            <origin xyz="0.0 0.0 0.4" rpy="0.0 0.0 0.0"/>   
        </visual>
    </link>

    <joint name="link_02_to_link_03" type="revolute">
        <axis xyz="0 1 0"/>
        <limit lower="-3.14" upper="3.14" effort="1000.0" velocity="0.5"/>
        <origin xyz="0.0 0.0 0.8" rpy="0.0 0.0 0.0"/>
        <parent link="link_02"/>
        <child link="link_03"/>
    </joint>

    <link name="link_03">
        <visual>
            <geometry>
                <cylinder length="0.8" radius="0.15"/>
            </geometry>
            <origin xyz="0.0 0.0 0.4" rpy="0.0 0.0 0.0"/>   
        </visual>
    </link>

     <joint name="link_03_to_link_04" type="revolute">
        <axis xyz="0 1 0"/>
        <limit lower="-3.14" upper="3.14" effort="1000.0" velocity="0.5"/>
        <origin xyz="0.0 0.0 0.8" rpy="0.0 0.0 0.0"/>
        <parent link="link_03"/>
        <child link="link_04"/>
    </joint>

    <link name="link_04">
        <visual>
            <geometry>
                <cylinder length="0.8" radius="0.15"/>
            </geometry>
            <origin xyz="0.0 0.0 0.4" rpy="0.0 0.0 0.0"/>   
        </visual>
    </link>


</robot>  


