<?xml version="1.0"?>
<robot name="forklift">

    <link name="chassis">
      <visual>
        <geometry>
            <box size="1 1 1"/>
        </geometry> 
        <origin xyz="0.0 0.0 0.6" rpy="0.0 0.0 0.0"/>
      </visual>
    </link> 

   <link name="r_wheel">
      <visual>
        <geometry>
          <cylinder length="0.05" radius="0.15"/>
        </geometry>
        <origin xyz="0.0 0.0 0.0" rpy="1.57 0.0 0.0"/>
      </visual>
   </link>

    <joint name="chassis_to_r_wheel" type="continuous">
        <axis xyz="0 1 0"/>
        <limit lower="-3.14" upper="3.14" effort="1000.0" velocity="0.5"/>
        <origin xyz="0.3 0.5 0.15" rpy="0.0 0.0 0.0"/>
        <parent link="chassis"/>
        <child link="r_wheel"/>
    </joint>   

    <link name="l_wheel">
        <visual>
            <geometry>
                <cylinder length="0.05" radius="0.15"/>
            </geometry>
        <origin xyz="0.0 0.0 0.0" rpy="1.57 0.0 0.0"/>
      </visual>
    </link>
    
    <joint name="chassis_to_l_wheel" type="continuous">
         <axis xyz="0 1 0"/>
        <limit lower="-3.14" upper="3.14" effort="1000.0" velocity="0.5"/>
        <origin xyz="0.3 -0.5 0.15" rpy="0.0 0.0 0.0"/>
        <parent link="chassis"/>
        <child link="l_wheel"/>
    </joint>
     
     <link name="caster">
        <visual>
            <geometry>
                <sphere radius="0.1"/>
            </geometry>
      </visual>
    </link>

    <joint name="chassis_to_caster" type="fixed">
        <origin xyz="-0.3 0.0 0.1" rpy="0.0 0.0 0.0"/>
        <parent link="chassis"/>
        <child link="caster"/>
    </joint>

    
    <link name="r_rod">
      <visual>
        <geometry>
            <box size="0.1 0.1 3.5"/>
        </geometry> 
        <origin xyz="0.0 0.0 1.75" rpy="0.0 0.0 0.0"/>
      </visual>
    </link>     

    <joint name="chassis_to_r_rod" type="fixed">
        <origin  xyz="0.55 0.25 0.0" rpy="0.0 0.0 0.0"/>
        <parent link="chassis"/>
        <child link="r_rod"/>
    </joint>   

    <link name="l_rod">
      <visual>
        <geometry>
            <box size="0.1 0.1 3.5"/>
        </geometry> 
        <origin xyz="0.0 0.0 1.75" rpy="0.0 0.0 0.0"/>
      </visual>
    </link> 

    <joint name="chassis_to_l_rod" type="fixed">
        <origin  xyz="0.55 -0.25 0.0" rpy="0.0 0.0 0.0"/>
        <parent link="chassis"/>
        <child link="l_rod"/>
    </joint>   

    <link name="lift">
      <visual>
        <geometry>
            <box size="1 0.8 0.02"/>
        </geometry> 
        <origin xyz="0.5 0.0 0.0" rpy="0.0 0.0 0.0"/>
      </visual>
    </link>

  <joint name="lift_t0_r_rod" type="prismatic">
         <axis xyz="0 0 1"/>
        <limit lower="0.0" upper="3.0" effort="1000.0" velocity="0.5"/>
        <origin xyz="0.05 -0.25 0.0" rpy="0.0 0.0 0.0"/>
        <parent link="r_rod"/>
        <child link="lift"/>
    </joint>

    <link name="pull_mech_v">
      <visual>
        <geometry>
            <box size="0.1 0.08 0.26"/>
        </geometry> 
        <origin xyz="0.0 0.0 0.13" rpy="0.0 0.0 0.0"/>
      </visual>
    </link>

    <joint name="lift_to_pull_mech_v" type="prismatic">
         <axis xyz="1 0 0"/>
        <limit lower="0.0" upper="0.8" effort="1000.0" velocity="0.5"/>
        <origin xyz="0.0 0.0 0.0" rpy="0.0 0.0 0.0"/>
        <parent link="lift"/>
        <child link="pull_mech_v"/>
    </joint>

    <link name="pull_mech_h">
        <visual>
            <geometry>
                <cylinder length="0.3" radius="0.04"/>
            </geometry>
        <origin xyz="0.2 0.0 0.0" rpy="0 1.57 0.0"/>
      </visual>
    </link>

    <joint name="pull_mech_v_to_pull_mech_h" type="fixed">
        <origin  xyz="0.0 0.0 0.2" rpy="0.0 0.0 0.0"/>
        <parent link="pull_mech_v"/>
        <child link="pull_mech_h"/>
    </joint> 

</robot>